<!-- 
Author: Yi Herng Ong
Purpose: XML model of j2s7s300 kinova jaco arm


 -->

<mujoco model="j2s7s300">
    <compiler angle="radian" meshdir="meshes/" />
    <size njmax="500" nconmax="100" />
    <asset>
    	<!-- Arm -->
        <mesh name="base" file="base.STL" />
        <mesh name="link_1" file="shoulder.STL" />
        <mesh name="link_2" file="arm_half_1.STL" />
        <mesh name="link_3" file="arm_half_2.STL" />
        <mesh name="link_4" file="forearm.STL" />
        <mesh name="link_5" file="wrist_spherical_1.STL" />
        <mesh name="link_6" file="wrist_spherical_2.STL" />
        <mesh name="link_7" file="hand_3finger.STL" />
        <!-- Fingers -->
        <mesh name="finger_distal" file="finger_distal.STL"/>
        <mesh name="finger_proximal" file="finger_proximal.STL"/>
    </asset>
    <worldbody>
    	<body name="root" pos="0 0 0">
	    <camera name="camera2" mode = "fixed" pos = "0.4270375 -0.05 0.55" axisangle = " 0 -0.1107235 0.9938512  3.1610291" fovy = "55.2136" />
<!--             <camera name="camera" pos = "0.4270375 -0.01254375 0.507375" axisangle = " 0 -0.1107235 0.9938512  3.1415" fovy = "45"/> -->
<!--             <camera name="camera" pos = "-0.03254375 -0.4270375 5" quat = "0 -0.1107182 0.9938043 -0.009718" fovy = "45"/>
            <camera name="camera" mode = "fixed" pos = "0 0.1 0.1" quat = "0 -90 0 0"/> -->

            <inertial pos="0 0 0" mass="0.001" diaginertia="1.66667e-08 1.66667e-08 1.66667e-08" />
            <geom size="0.005 0.005 0.005" type="box" />


            <body name="j2s7s300_link_base" pos="0 0 0">
            	<inertial pos="0 0 0.1255" mass="0.46784" diaginertia="0.000951271 0.000951271 0.000374272" />
				<geom type="mesh" rgba="0.792157 0.819608 0.933333 1" mesh="base" />


				<body name="j2s7s300_link_1" pos="0 0 0.15675" quat="0 0 1 0">
					<inertial pos="0 -0.002 -0.0605" mass="0.7477" diaginertia="0.00152032 0.00152032 0.00059816" />
					<joint name="j2s7s300_joint_1" pos="0 0 0" axis="0 0 -1" limited="true" range="-6.28319 6.28319" />
					<geom type="mesh" rgba="0.792157 0.819608 0.933333 1" mesh="link_1"/>


					<body name="j2s7s300_link_2" pos="0 0.0016 -0.11875" quat="-0.707107 -0.707107 0 0">
						<inertial pos="0 -0.145 -0.0076" quat="0.707107 0.707107 0 0" mass="0.85968" diaginertia="0.00467091 0.00467091 0.000386856" />
						<joint name="j2s7s300_joint_2" pos="0 0 0" axis="0 0 1" limited="true" range="0.81988 5.460"/>
						<geom type="mesh" rgba="0.792157 0.819608 0.933333 1" mesh="link_2"/>


						<body name="j2s7s300_link_3" pos="0 -0.205 0" quat="0 0 -0.7071 -0.7071">
							<inertial pos="0 0.0463 -0.0065" quat="0.707107 0.707107 0 0" mass="0.606" diaginertia="0.000383798 0.000383798 0.0001212" />
							<joint name="j2s7s300_joint_3" pos="0 0 0" axis="0 0 1" limited="true" range="-6.28319 6.28319" />
							<geom type="mesh" rgba="0.792157 0.819608 0.933333 1" mesh="link_3"/>


							<body name= "j2s7s300_link_4" pos="0 0 -0.205" quat="0 0 0.7071 0.7071">
								<inertial pos="0 -0.037 -0.0642" quat="0.5 0.5 -0.5 0.5" mass="0.1785" diaginertia="0.0001428 7.73497e-05 7.73497e-05" />
								<joint name="j2s7s300_joint_4" pos="0 0 0" axis="0 0 1" limited="true" range="0.52333 5.75666" />
								<geom type="mesh" rgba="0.792157 0.819608 0.933333 1" mesh="link_4"/>


								<body name="j2s7s300_link_5" pos="0 0.2073 -0.0114" quat="0 0 -0.7071 0.7071">
									<inertial pos="0 -0.037 -0.0642" quat="0.5 0.5 -0.5 0.5" mass="0.1785" diaginertia="0.0001428 7.73497e-05 7.73497e-05" />
									<joint name="j2s7s300_joint_5" pos="0 0 0" axis="0 0 1" limited="true" range="-6.28319 6.28319" />
									<geom type="mesh" rgba="0.792157 0.819608 0.933333 1" mesh="link_5"/>


									<body name="j2s7s300_link_6" pos="0 0 -0.10375" quat="0 0 0.707 0.707">
										<inertial pos="0 0 -0.06" quat="0.5 0.5 -0.5 0.5" mass="0.727" diaginertia="0.0005816 0.000345324 0.000345324" />
										<joint name="j2s7s300_joint_6" pos="0 0 0" axis="0 0 1" limited="true" range="1.13388 5.1461" />
										<geom type="mesh" rgba="0.792157 0.819608 0.933333 1" mesh="link_6"/>


										<body name="j2s7s300_link_7" pos="0 0.10375 0" quat="0 0 -0.707 0.707">
											<inertial pos="0 0 -0.06" quat="0.5 0.5 -0.5 0.5" mass="0.727" diaginertia="0.0005816 0.000345324 0.000345324" />
											<joint name="j2s7s300_joint_7" pos="0 0 0" axis="0 0 1" limited="true" range="-6.28319 6.28319" />
											<geom type="mesh" rgba="0.792157 0.819608 0.933333 1" mesh="link_7"/>


											<body name="j2s7s300_end_effector" pos="0 0 -0.16" quat="0 1 0 0">
												<inertial pos="0 0 -0.16" quat="0 1 0 0" mass="0" diaginertia="0 0 0" />
											</body>


											<body name="j2s7s300_link_finger_1" pos="0.00279 0.03126 -0.11467" quat="0.379408 -0.662973 -0.245899 0.596699">
												<inertial pos="0.022 0 0" mass="0.01" diaginertia="7.89997e-07 7.89997e-07 8e-08" />
												<joint name="j2s7s300_joint_finger_1" pos="0 0 0" axis="0 0 1" limited="true" range="0 2" />
												<geom type="mesh" rgba="0.792157 0.819608 0.933333 1" mesh="finger_proximal" />


												<body name="j2s7s300_link_finger_tip_1" pos="0.044 -0.003 0">
													<inertial pos="0.022 0 0" mass="0.01" diaginertia="7.89997e-07 7.89997e-07 8e-08" />
													<geom type="mesh" rgba="0.792157 0.819608 0.933333 1" mesh="finger_distal" />
												</body>


											</body>


											<body name="j2s7s300_link_finger_2" pos="0.02226 -0.02707 -0.11482" quat="0.659653 -0.37146 0.601679 -0.254671">
												<inertial pos="0.022 0 0" mass="0.01" diaginertia="7.89997e-07 7.89997e-07 8e-08" />
												<joint name="j2s7s300_joint_finger_2" pos="0 0 0" axis="0 0 1" limited="true" range="0 2" />
												<geom type="mesh" rgba="0.792157 0.819608 0.933333 1" mesh="finger_proximal" />


												<body name="j2s7s300_link_finger_tip_2" pos="0.044 -0.003 0">
													<inertial pos="0.022 0 0" mass="0.01" diaginertia="7.89997e-07 7.89997e-07 8e-08" />
													<geom type="mesh" rgba="0.792157 0.819608 0.933333 1" mesh="finger_distal" />
												</body>


											</body>


											<body name="j2s7s300_link_finger_3" pos="-0.02226 -0.02707 -0.11482" quat="0.601679 -0.254671 0.659653 -0.37146">
												<inertial pos="0.022 0 0" mass="0.01" diaginertia="7.89997e-07 7.89997e-07 8e-08" />
												<joint name="j2s7s300_joint_finger_3" pos="0 0 0" axis="0 0 1" limited="true" range="0 2" />
												<geom type="mesh" rgba="0.792157 0.819608 0.933333 1" mesh="finger_proximal" />


												<body name="j2s7s300_link_finger_tip_3" pos="0.044 -0.003 0">
													<inertial pos="0.022 0 0" mass="0.01" diaginertia="7.89997e-07 7.89997e-07 8e-08" />
													<geom type="mesh" rgba="0.792157 0.819608 0.933333 1" mesh="finger_distal" />
												</body>


											</body>
										</body>
									</body>								
								</body>
							</body>	
						</body>					
					</body>
				</body>    		
    		</body>
    	</body>

		<body name="ground" pos="1 1 -3">
			<geom condim="3" size="2.0 3.0 0.02" rgba="1 1 0.8 1" type="plane"/>
		</body>

<!--		<body name="cube" pos="0.5 0.0 0.0375">
			<joint type="free"/>
			<geom name="cube" mass="0.0884" size="0.0375 0.0375 0.0375" rgba="1 0 0 1" type="box"/> 
		</body>
-->
    </worldbody>
	<!-- ======================= Velocity actuators ================================ -->
<!-- 	<actuator>
		<velocity joint="j2s7s300_joint_1" kv="10" forcelimited="true" forcerange="-2000 2000" ctrllimited="true" ctrlrange="-6.28319 6.28319"></velocity>
		<velocity joint="j2s7s300_joint_2" kv="40" forcelimited="true" forcerange="-2000 2000" ctrllimited="true" ctrlrange="-2.35 2.35"></velocity>
		<velocity joint="j2s7s300_joint_3" kv="40" forcelimited="true" forcerange="-2000 2000" ctrllimited="true" ctrlrange="-6.28319 6.28319"></velocity>
		<velocity joint="j2s7s300_joint_4" kv="10" forcelimited="true" forcerange="-2000 2000" ctrllimited="true" ctrlrange="0.52333 5.75666"></velocity>
		<velocity joint="j2s7s300_joint_5" kv="4" forcelimited="true" forcerange="-2000 2000" ctrllimited="true" ctrlrange="-6.28319 6.28319"></velocity>
		<velocity joint="j2s7s300_joint_6" kv="10" forcelimited="true" forcerange="-2000 2000" ctrllimited="true" ctrlrange="1.13388 5.1461"></velocity>
		<velocity joint="j2s7s300_joint_7" kv="2" forcelimited="true" forcerange="-2000 2000" ctrllimited="true" ctrlrange="-6.28319 6.28319"></velocity>
		<position joint="j2s7s300_joint_finger_1" kp="5"  ctrllimited="true" ctrlrange="0 2"></position>
		<position joint="j2s7s300_joint_finger_2" kp="5"  ctrllimited="true" ctrlrange="0 2"></position>
		<position joint="j2s7s300_joint_finger_3" kp="5"  ctrllimited="true" ctrlrange="0 2"></position>
	</actuator> -->
	<!-- ======================= Position actuators ================================ -->
<!-- 	<actuator>
		<position joint="j2s7s300_joint_1" kp="1" ctrllimited="true" ctrlrange="-6.28319 6.28319"></position>
		<position joint="j2s7s300_joint_2" kp="1" ctrllimited="true" ctrlrange="0.81988 5.460"></position>
		<position joint="j2s7s300_joint_3" kp="1" ctrllimited="true" ctrlrange="-6.28319 6.28319"></position>
		<position joint="j2s7s300_joint_4" kp="1" ctrllimited="true" ctrlrange="0.52333 5.75666"></position>
		<position joint="j2s7s300_joint_5" kp="1" ctrllimited="true" ctrlrange="-6.28319 6.28319"></position>
		<position joint="j2s7s300_joint_6" kp="1" ctrllimited="true" ctrlrange="1.13388 5.1461"></position>
		<position joint="j2s7s300_joint_7" kp="1" ctrllimited="true" ctrlrange="-6.28319 6.28319"></position>
		<position joint="j2s7s300_joint_finger_1" kp="1"  ctrllimited="true" ctrlrange="0 2"></position>
		<position joint="j2s7s300_joint_finger_2" kp="1"  ctrllimited="true" ctrlrange="0 2"></position>
		<position joint="j2s7s300_joint_finger_3" kp="1"  ctrllimited="true" ctrlrange="0 2"></position>
	</actuator> -->

	<!-- ======================= Torque actuators ================================ -->
	<actuator>
		<motor joint='j2s7s300_joint_1' name='j2s7s300_joint_1_act' gear="10" />
		<motor joint='j2s7s300_joint_2' name='j2s7s300_joint_2_act' gear="20" forcerange='-1000 1000' forcelimited='true' ctrlrange='-6.28319 6.28319' ctrllimited='true'/>
		<motor joint='j2s7s300_joint_3' name='j2s7s300_joint_3_act' gear="10" forcerange='-10 10' forcelimited='true' ctrlrange='-6.28319 6.28319' ctrllimited='true'/>
		<motor joint='j2s7s300_joint_4' name='j2s7s300_joint_4_act' gear="10" forcerange='-10 10' forcelimited='true' ctrlrange='-6.28319 6.28319' ctrllimited='true'/>
		<motor joint='j2s7s300_joint_5' name='j2s7s300_joint_5_act' gear="10" forcerange='-10 10' forcelimited='true' ctrlrange='-6.28319 6.28319' ctrllimited='true' />
		<motor joint='j2s7s300_joint_6' name='j2s7s300_joint_6_act' gear="10" forcerange='-10 10' forcelimited='true' ctrlrange='-6.28319 6.28319' ctrllimited='true'/>
		<motor joint='j2s7s300_joint_7' name='j2s7s300_joint_7_act' gear="10" forcerange='-10 10' forcelimited='true' ctrlrange='-6.28319 6.28319' ctrllimited='true'/>
		<motor joint='j2s7s300_joint_finger_1' name='j2s7s300_joint_finger_1_act' gear="10" forcerange='-10 10' forcelimited='true' ctrlrange='-6.28319 6.28319' ctrllimited='true'/>
		<motor joint='j2s7s300_joint_finger_2' name='j2s7s300_joint_finger_2_act' gear="10" forcerange='-10 10' forcelimited='true' ctrlrange='-6.28319 6.28319' ctrllimited='true'/>
		<motor joint='j2s7s300_joint_finger_3' name='j2s7s300_joint_finger_3_act' gear="10" forcerange='-10 10' forcelimited='true' ctrlrange='-6.28319 6.28319' ctrllimited='true'/>
	</actuator>
    <sensor>
        <jointpos joint='j2s7s300_joint_1'/>
        <jointpos joint='j2s7s300_joint_2'/>
        <jointpos joint='j2s7s300_joint_3'/>
        <jointpos joint='j2s7s300_joint_4'/>
        <jointpos joint='j2s7s300_joint_5'/>
        <jointpos joint='j2s7s300_joint_6'/>
	<jointpos joint='j2s7s300_joint_7'/>
        <jointpos joint='j2s7s300_joint_finger_1'/>
        <jointpos joint='j2s7s300_joint_finger_2'/>
        <jointpos joint='j2s7s300_joint_finger_3'/>
    </sensor>
</mujoco>
